{
 "cells": [
  {
   "cell_type": "code",
   "execution_count": 1,
   "metadata": {},
   "outputs": [],
   "source": [
    "import nest_asyncio\n",
    "nest_asyncio.apply()"
   ]
  },
  {
   "cell_type": "code",
   "execution_count": null,
   "metadata": {},
   "outputs": [
    {
     "name": "stdout",
     "output_type": "stream",
     "text": [
      "Outer start\n",
      "Outer end\n",
      "Inner start\n",
      "Inner end\n"
     ]
    }
   ],
   "source": [
    "# task가 중첩되는 경우 실행 결과는?\n",
    "\n",
    "import asyncio\n",
    "\n",
    "async def inner():\n",
    "    print(\"Inner start\")\n",
    "    await asyncio.sleep(1)\n",
    "    print(\"Inner end\")\n",
    "\n",
    "async def outer():\n",
    "    print(\"Outer start\")\n",
    "    task = asyncio.create_task(inner())\n",
    "    print(\"Outer end\")\n",
    "    await task \n",
    "\n",
    "asyncio.run(outer())"
   ]
  },
  {
   "cell_type": "code",
   "execution_count": 3,
   "metadata": {},
   "outputs": [
    {
     "name": "stdout",
     "output_type": "stream",
     "text": [
      "\n",
      "=== ProcessPoolExecutor ===\n",
      "IO-1: Start I/O task\n",
      "IO-2: Start I/O task\n"
     ]
    },
    {
     "name": "stderr",
     "output_type": "stream",
     "text": [
      "Process SpawnProcess-1:\n",
      "Process SpawnProcess-2:\n",
      "Traceback (most recent call last):\n",
      "Traceback (most recent call last):\n",
      "  File \"/Users/kihoon/.pyenv/versions/3.13.0/lib/python3.13/multiprocessing/process.py\", line 313, in _bootstrap\n",
      "    self.run()\n",
      "    ~~~~~~~~^^\n",
      "  File \"/Users/kihoon/.pyenv/versions/3.13.0/lib/python3.13/multiprocessing/process.py\", line 108, in run\n",
      "    self._target(*self._args, **self._kwargs)\n",
      "    ~~~~~~~~~~~~^^^^^^^^^^^^^^^^^^^^^^^^^^^^^\n",
      "  File \"/Users/kihoon/.pyenv/versions/3.13.0/lib/python3.13/concurrent/futures/process.py\", line 241, in _process_worker\n",
      "    call_item = call_queue.get(block=True)\n",
      "  File \"/Users/kihoon/.pyenv/versions/3.13.0/lib/python3.13/multiprocessing/queues.py\", line 120, in get\n",
      "    return _ForkingPickler.loads(res)\n",
      "           ~~~~~~~~~~~~~~~~~~~~~^^^^^\n",
      "AttributeError: Can't get attribute 'cpu_bound_task' on <module '__main__' (<class '_frozen_importlib.BuiltinImporter'>)>\n",
      "  File \"/Users/kihoon/.pyenv/versions/3.13.0/lib/python3.13/multiprocessing/process.py\", line 313, in _bootstrap\n",
      "    self.run()\n",
      "    ~~~~~~~~^^\n",
      "  File \"/Users/kihoon/.pyenv/versions/3.13.0/lib/python3.13/multiprocessing/process.py\", line 108, in run\n",
      "    self._target(*self._args, **self._kwargs)\n",
      "    ~~~~~~~~~~~~^^^^^^^^^^^^^^^^^^^^^^^^^^^^^\n",
      "  File \"/Users/kihoon/.pyenv/versions/3.13.0/lib/python3.13/concurrent/futures/process.py\", line 241, in _process_worker\n",
      "    call_item = call_queue.get(block=True)\n",
      "  File \"/Users/kihoon/.pyenv/versions/3.13.0/lib/python3.13/multiprocessing/queues.py\", line 120, in get\n",
      "    return _ForkingPickler.loads(res)\n",
      "           ~~~~~~~~~~~~~~~~~~~~~^^^^^\n",
      "AttributeError: Can't get attribute 'cpu_bound_task' on <module '__main__' (<class '_frozen_importlib.BuiltinImporter'>)>\n"
     ]
    },
    {
     "ename": "BrokenProcessPool",
     "evalue": "A process in the process pool was terminated abruptly while the future was running or pending.",
     "output_type": "error",
     "traceback": [
      "\u001b[31m---------------------------------------------------------------------------\u001b[39m",
      "\u001b[31mBrokenProcessPool\u001b[39m                         Traceback (most recent call last)",
      "\u001b[36mCell\u001b[39m\u001b[36m \u001b[39m\u001b[32mIn[3]\u001b[39m\u001b[32m, line 43\u001b[39m\n\u001b[32m     41\u001b[39m \u001b[38;5;28mprint\u001b[39m(\u001b[33m\"\u001b[39m\u001b[38;5;130;01m\\n\u001b[39;00m\u001b[33m=== ProcessPoolExecutor ===\u001b[39m\u001b[33m\"\u001b[39m)\n\u001b[32m     42\u001b[39m \u001b[38;5;28;01mwith\u001b[39;00m concurrent.futures.ProcessPoolExecutor() \u001b[38;5;28;01mas\u001b[39;00m executor:\n\u001b[32m---> \u001b[39m\u001b[32m43\u001b[39m     \u001b[43masyncio\u001b[49m\u001b[43m.\u001b[49m\u001b[43mrun\u001b[49m\u001b[43m(\u001b[49m\u001b[43mmain\u001b[49m\u001b[43m(\u001b[49m\u001b[43mexecutor\u001b[49m\u001b[43m)\u001b[49m\u001b[43m)\u001b[49m\n",
      "\u001b[36mFile \u001b[39m\u001b[32m~/.pyenv/versions/3.13.0/lib/python3.13/site-packages/nest_asyncio.py:30\u001b[39m, in \u001b[36m_patch_asyncio.<locals>.run\u001b[39m\u001b[34m(main, debug)\u001b[39m\n\u001b[32m     28\u001b[39m task = asyncio.ensure_future(main)\n\u001b[32m     29\u001b[39m \u001b[38;5;28;01mtry\u001b[39;00m:\n\u001b[32m---> \u001b[39m\u001b[32m30\u001b[39m     \u001b[38;5;28;01mreturn\u001b[39;00m \u001b[43mloop\u001b[49m\u001b[43m.\u001b[49m\u001b[43mrun_until_complete\u001b[49m\u001b[43m(\u001b[49m\u001b[43mtask\u001b[49m\u001b[43m)\u001b[49m\n\u001b[32m     31\u001b[39m \u001b[38;5;28;01mfinally\u001b[39;00m:\n\u001b[32m     32\u001b[39m     \u001b[38;5;28;01mif\u001b[39;00m \u001b[38;5;129;01mnot\u001b[39;00m task.done():\n",
      "\u001b[36mFile \u001b[39m\u001b[32m~/.pyenv/versions/3.13.0/lib/python3.13/site-packages/nest_asyncio.py:98\u001b[39m, in \u001b[36m_patch_loop.<locals>.run_until_complete\u001b[39m\u001b[34m(self, future)\u001b[39m\n\u001b[32m     95\u001b[39m \u001b[38;5;28;01mif\u001b[39;00m \u001b[38;5;129;01mnot\u001b[39;00m f.done():\n\u001b[32m     96\u001b[39m     \u001b[38;5;28;01mraise\u001b[39;00m \u001b[38;5;167;01mRuntimeError\u001b[39;00m(\n\u001b[32m     97\u001b[39m         \u001b[33m'\u001b[39m\u001b[33mEvent loop stopped before Future completed.\u001b[39m\u001b[33m'\u001b[39m)\n\u001b[32m---> \u001b[39m\u001b[32m98\u001b[39m \u001b[38;5;28;01mreturn\u001b[39;00m \u001b[43mf\u001b[49m\u001b[43m.\u001b[49m\u001b[43mresult\u001b[49m\u001b[43m(\u001b[49m\u001b[43m)\u001b[49m\n",
      "\u001b[36mFile \u001b[39m\u001b[32m~/.pyenv/versions/3.13.0/lib/python3.13/asyncio/futures.py:200\u001b[39m, in \u001b[36mFuture.result\u001b[39m\u001b[34m(self)\u001b[39m\n\u001b[32m    198\u001b[39m \u001b[38;5;28mself\u001b[39m.__log_traceback = \u001b[38;5;28;01mFalse\u001b[39;00m\n\u001b[32m    199\u001b[39m \u001b[38;5;28;01mif\u001b[39;00m \u001b[38;5;28mself\u001b[39m._exception \u001b[38;5;129;01mis\u001b[39;00m \u001b[38;5;129;01mnot\u001b[39;00m \u001b[38;5;28;01mNone\u001b[39;00m:\n\u001b[32m--> \u001b[39m\u001b[32m200\u001b[39m     \u001b[38;5;28;01mraise\u001b[39;00m \u001b[38;5;28mself\u001b[39m._exception.with_traceback(\u001b[38;5;28mself\u001b[39m._exception_tb)\n\u001b[32m    201\u001b[39m \u001b[38;5;28;01mreturn\u001b[39;00m \u001b[38;5;28mself\u001b[39m._result\n",
      "\u001b[36mFile \u001b[39m\u001b[32m~/.pyenv/versions/3.13.0/lib/python3.13/asyncio/tasks.py:306\u001b[39m, in \u001b[36mTask.__step_run_and_handle_result\u001b[39m\u001b[34m(***failed resolving arguments***)\u001b[39m\n\u001b[32m    304\u001b[39m         result = coro.send(\u001b[38;5;28;01mNone\u001b[39;00m)\n\u001b[32m    305\u001b[39m     \u001b[38;5;28;01melse\u001b[39;00m:\n\u001b[32m--> \u001b[39m\u001b[32m306\u001b[39m         result = \u001b[43mcoro\u001b[49m\u001b[43m.\u001b[49m\u001b[43mthrow\u001b[49m\u001b[43m(\u001b[49m\u001b[43mexc\u001b[49m\u001b[43m)\u001b[49m\n\u001b[32m    307\u001b[39m \u001b[38;5;28;01mexcept\u001b[39;00m \u001b[38;5;167;01mStopIteration\u001b[39;00m \u001b[38;5;28;01mas\u001b[39;00m exc:\n\u001b[32m    308\u001b[39m     \u001b[38;5;28;01mif\u001b[39;00m \u001b[38;5;28mself\u001b[39m._must_cancel:\n\u001b[32m    309\u001b[39m         \u001b[38;5;66;03m# Task is cancelled right before coro stops.\u001b[39;00m\n",
      "\u001b[36mCell\u001b[39m\u001b[36m \u001b[39m\u001b[32mIn[3]\u001b[39m\u001b[32m, line 30\u001b[39m, in \u001b[36mmain\u001b[39m\u001b[34m(executor)\u001b[39m\n\u001b[32m     22\u001b[39m tasks = [\n\u001b[32m     23\u001b[39m     loop.run_in_executor(executor, cpu_bound_task, \u001b[33m\"\u001b[39m\u001b[33mCPU-1\u001b[39m\u001b[33m\"\u001b[39m),\n\u001b[32m     24\u001b[39m     loop.run_in_executor(executor, cpu_bound_task, \u001b[33m\"\u001b[39m\u001b[33mCPU-2\u001b[39m\u001b[33m\"\u001b[39m),\n\u001b[32m     25\u001b[39m     asyncio.create_task(io_bound_task(\u001b[33m\"\u001b[39m\u001b[33mIO-1\u001b[39m\u001b[33m\"\u001b[39m)),\n\u001b[32m     26\u001b[39m     asyncio.create_task(io_bound_task(\u001b[33m\"\u001b[39m\u001b[33mIO-2\u001b[39m\u001b[33m\"\u001b[39m))\n\u001b[32m     27\u001b[39m ]\n\u001b[32m     29\u001b[39m start = time.time()\n\u001b[32m---> \u001b[39m\u001b[32m30\u001b[39m results = \u001b[38;5;28;01mawait\u001b[39;00m asyncio.gather(*tasks)\n\u001b[32m     31\u001b[39m end = time.time()\n\u001b[32m     33\u001b[39m \u001b[38;5;28mprint\u001b[39m(\u001b[33mf\u001b[39m\u001b[33m\"\u001b[39m\u001b[33mResults: \u001b[39m\u001b[38;5;132;01m{\u001b[39;00mresults\u001b[38;5;132;01m}\u001b[39;00m\u001b[33m\"\u001b[39m)\n",
      "\u001b[36mFile \u001b[39m\u001b[32m~/.pyenv/versions/3.13.0/lib/python3.13/asyncio/tasks.py:375\u001b[39m, in \u001b[36mTask.__wakeup\u001b[39m\u001b[34m(self, future)\u001b[39m\n\u001b[32m    373\u001b[39m \u001b[38;5;28;01mdef\u001b[39;00m\u001b[38;5;250m \u001b[39m\u001b[34m__wakeup\u001b[39m(\u001b[38;5;28mself\u001b[39m, future):\n\u001b[32m    374\u001b[39m     \u001b[38;5;28;01mtry\u001b[39;00m:\n\u001b[32m--> \u001b[39m\u001b[32m375\u001b[39m         \u001b[43mfuture\u001b[49m\u001b[43m.\u001b[49m\u001b[43mresult\u001b[49m\u001b[43m(\u001b[49m\u001b[43m)\u001b[49m\n\u001b[32m    376\u001b[39m     \u001b[38;5;28;01mexcept\u001b[39;00m \u001b[38;5;167;01mBaseException\u001b[39;00m \u001b[38;5;28;01mas\u001b[39;00m exc:\n\u001b[32m    377\u001b[39m         \u001b[38;5;66;03m# This may also be a cancellation.\u001b[39;00m\n\u001b[32m    378\u001b[39m         \u001b[38;5;28mself\u001b[39m.__step(exc)\n",
      "\u001b[31mBrokenProcessPool\u001b[39m: A process in the process pool was terminated abruptly while the future was running or pending."
     ]
    },
    {
     "name": "stdout",
     "output_type": "stream",
     "text": [
      "IO-1: End I/O task\n",
      "IO-2: End I/O task\n"
     ]
    }
   ],
   "source": [
    "import asyncio\n",
    "import concurrent.futures\n",
    "import time\n",
    "\n",
    "def cpu_bound_task(name):\n",
    "    print(f\"{name}: Start heavy CPU work\")\n",
    "    count = 0\n",
    "    for _ in range(10 ** 7):\n",
    "        count += 1\n",
    "    print(f\"{name}: End heavy CPU work\")\n",
    "    return count\n",
    "\n",
    "async def io_bound_task(name):\n",
    "    print(f\"{name}: Start I/O task\")\n",
    "    await asyncio.sleep(2)\n",
    "    print(f\"{name}: End I/O task\")\n",
    "\n",
    "async def main(executor):\n",
    "    loop = asyncio.get_running_loop()\n",
    "\n",
    "    # CPU 바운드 작업 2개 + I/O 바운드 작업 2개 실행\n",
    "    tasks = [\n",
    "        loop.run_in_executor(executor, cpu_bound_task, \"CPU-1\"),\n",
    "        loop.run_in_executor(executor, cpu_bound_task, \"CPU-2\"),\n",
    "        asyncio.create_task(io_bound_task(\"IO-1\")),\n",
    "        asyncio.create_task(io_bound_task(\"IO-2\"))\n",
    "    ]\n",
    "\n",
    "    start = time.time()\n",
    "    results = await asyncio.gather(*tasks)\n",
    "    end = time.time()\n",
    "\n",
    "    print(f\"Results: {results}\")\n",
    "    print(f\"Total time: {end - start:.2f} seconds\")\n",
    "\n",
    "if __name__ == \"__main__\":\n",
    "    # print(\"=== ThreadPoolExecutor ===\")\n",
    "    # with concurrent.futures.ThreadPoolExecutor() as executor:\n",
    "    #     asyncio.run(main(executor))\n",
    "\n",
    "    print(\"\\n=== ProcessPoolExecutor ===\")\n",
    "    with concurrent.futures.ProcessPoolExecutor() as executor:\n",
    "        asyncio.run(main(executor))"
   ]
  },
  {
   "cell_type": "code",
   "execution_count": 5,
   "metadata": {},
   "outputs": [
    {
     "name": "stderr",
     "output_type": "stream",
     "text": [
      "Process SpawnProcess-4:\n",
      "Traceback (most recent call last):\n",
      "  File \"/Users/kihoon/.pyenv/versions/3.13.0/lib/python3.13/multiprocessing/process.py\", line 313, in _bootstrap\n",
      "    self.run()\n",
      "    ~~~~~~~~^^\n",
      "  File \"/Users/kihoon/.pyenv/versions/3.13.0/lib/python3.13/multiprocessing/process.py\", line 108, in run\n",
      "    self._target(*self._args, **self._kwargs)\n",
      "    ~~~~~~~~~~~~^^^^^^^^^^^^^^^^^^^^^^^^^^^^^\n",
      "  File \"/Users/kihoon/.pyenv/versions/3.13.0/lib/python3.13/concurrent/futures/process.py\", line 241, in _process_worker\n",
      "    call_item = call_queue.get(block=True)\n",
      "  File \"/Users/kihoon/.pyenv/versions/3.13.0/lib/python3.13/multiprocessing/queues.py\", line 120, in get\n",
      "    return _ForkingPickler.loads(res)\n",
      "           ~~~~~~~~~~~~~~~~~~~~~^^^^^\n",
      "AttributeError: Can't get attribute 'cpu_bound_task' on <module '__main__' (<class '_frozen_importlib.BuiltinImporter'>)>\n"
     ]
    },
    {
     "ename": "BrokenProcessPool",
     "evalue": "A process in the process pool was terminated abruptly while the future was running or pending.",
     "output_type": "error",
     "traceback": [
      "\u001b[31m---------------------------------------------------------------------------\u001b[39m",
      "\u001b[31mBrokenProcessPool\u001b[39m                         Traceback (most recent call last)",
      "\u001b[36mCell\u001b[39m\u001b[36m \u001b[39m\u001b[32mIn[5]\u001b[39m\u001b[32m, line 21\u001b[39m\n\u001b[32m     18\u001b[39m         \u001b[38;5;28mprint\u001b[39m(\u001b[33mf\u001b[39m\u001b[33m\"\u001b[39m\u001b[33mResult: \u001b[39m\u001b[38;5;132;01m{\u001b[39;00mresult\u001b[38;5;132;01m}\u001b[39;00m\u001b[33m\"\u001b[39m)\n\u001b[32m     20\u001b[39m \u001b[38;5;28;01mif\u001b[39;00m \u001b[34m__name__\u001b[39m == \u001b[33m'\u001b[39m\u001b[33m__main__\u001b[39m\u001b[33m'\u001b[39m:\n\u001b[32m---> \u001b[39m\u001b[32m21\u001b[39m     \u001b[43masyncio\u001b[49m\u001b[43m.\u001b[49m\u001b[43mrun\u001b[49m\u001b[43m(\u001b[49m\u001b[43mmain\u001b[49m\u001b[43m(\u001b[49m\u001b[43m)\u001b[49m\u001b[43m)\u001b[49m\n",
      "\u001b[36mFile \u001b[39m\u001b[32m~/.pyenv/versions/3.13.0/lib/python3.13/site-packages/nest_asyncio.py:30\u001b[39m, in \u001b[36m_patch_asyncio.<locals>.run\u001b[39m\u001b[34m(main, debug)\u001b[39m\n\u001b[32m     28\u001b[39m task = asyncio.ensure_future(main)\n\u001b[32m     29\u001b[39m \u001b[38;5;28;01mtry\u001b[39;00m:\n\u001b[32m---> \u001b[39m\u001b[32m30\u001b[39m     \u001b[38;5;28;01mreturn\u001b[39;00m \u001b[43mloop\u001b[49m\u001b[43m.\u001b[49m\u001b[43mrun_until_complete\u001b[49m\u001b[43m(\u001b[49m\u001b[43mtask\u001b[49m\u001b[43m)\u001b[49m\n\u001b[32m     31\u001b[39m \u001b[38;5;28;01mfinally\u001b[39;00m:\n\u001b[32m     32\u001b[39m     \u001b[38;5;28;01mif\u001b[39;00m \u001b[38;5;129;01mnot\u001b[39;00m task.done():\n",
      "\u001b[36mFile \u001b[39m\u001b[32m~/.pyenv/versions/3.13.0/lib/python3.13/site-packages/nest_asyncio.py:98\u001b[39m, in \u001b[36m_patch_loop.<locals>.run_until_complete\u001b[39m\u001b[34m(self, future)\u001b[39m\n\u001b[32m     95\u001b[39m \u001b[38;5;28;01mif\u001b[39;00m \u001b[38;5;129;01mnot\u001b[39;00m f.done():\n\u001b[32m     96\u001b[39m     \u001b[38;5;28;01mraise\u001b[39;00m \u001b[38;5;167;01mRuntimeError\u001b[39;00m(\n\u001b[32m     97\u001b[39m         \u001b[33m'\u001b[39m\u001b[33mEvent loop stopped before Future completed.\u001b[39m\u001b[33m'\u001b[39m)\n\u001b[32m---> \u001b[39m\u001b[32m98\u001b[39m \u001b[38;5;28;01mreturn\u001b[39;00m \u001b[43mf\u001b[49m\u001b[43m.\u001b[49m\u001b[43mresult\u001b[49m\u001b[43m(\u001b[49m\u001b[43m)\u001b[49m\n",
      "\u001b[36mFile \u001b[39m\u001b[32m~/.pyenv/versions/3.13.0/lib/python3.13/asyncio/futures.py:200\u001b[39m, in \u001b[36mFuture.result\u001b[39m\u001b[34m(self)\u001b[39m\n\u001b[32m    198\u001b[39m \u001b[38;5;28mself\u001b[39m.__log_traceback = \u001b[38;5;28;01mFalse\u001b[39;00m\n\u001b[32m    199\u001b[39m \u001b[38;5;28;01mif\u001b[39;00m \u001b[38;5;28mself\u001b[39m._exception \u001b[38;5;129;01mis\u001b[39;00m \u001b[38;5;129;01mnot\u001b[39;00m \u001b[38;5;28;01mNone\u001b[39;00m:\n\u001b[32m--> \u001b[39m\u001b[32m200\u001b[39m     \u001b[38;5;28;01mraise\u001b[39;00m \u001b[38;5;28mself\u001b[39m._exception.with_traceback(\u001b[38;5;28mself\u001b[39m._exception_tb)\n\u001b[32m    201\u001b[39m \u001b[38;5;28;01mreturn\u001b[39;00m \u001b[38;5;28mself\u001b[39m._result\n",
      "\u001b[36mFile \u001b[39m\u001b[32m~/.pyenv/versions/3.13.0/lib/python3.13/asyncio/tasks.py:306\u001b[39m, in \u001b[36mTask.__step_run_and_handle_result\u001b[39m\u001b[34m(***failed resolving arguments***)\u001b[39m\n\u001b[32m    304\u001b[39m         result = coro.send(\u001b[38;5;28;01mNone\u001b[39;00m)\n\u001b[32m    305\u001b[39m     \u001b[38;5;28;01melse\u001b[39;00m:\n\u001b[32m--> \u001b[39m\u001b[32m306\u001b[39m         result = \u001b[43mcoro\u001b[49m\u001b[43m.\u001b[49m\u001b[43mthrow\u001b[49m\u001b[43m(\u001b[49m\u001b[43mexc\u001b[49m\u001b[43m)\u001b[49m\n\u001b[32m    307\u001b[39m \u001b[38;5;28;01mexcept\u001b[39;00m \u001b[38;5;167;01mStopIteration\u001b[39;00m \u001b[38;5;28;01mas\u001b[39;00m exc:\n\u001b[32m    308\u001b[39m     \u001b[38;5;28;01mif\u001b[39;00m \u001b[38;5;28mself\u001b[39m._must_cancel:\n\u001b[32m    309\u001b[39m         \u001b[38;5;66;03m# Task is cancelled right before coro stops.\u001b[39;00m\n",
      "\u001b[36mCell\u001b[39m\u001b[36m \u001b[39m\u001b[32mIn[5]\u001b[39m\u001b[32m, line 17\u001b[39m, in \u001b[36mmain\u001b[39m\u001b[34m()\u001b[39m\n\u001b[32m     15\u001b[39m \u001b[38;5;66;03m# CPU 바운드 작업을 ProcessPoolExecutor 로 분리\u001b[39;00m\n\u001b[32m     16\u001b[39m \u001b[38;5;28;01mwith\u001b[39;00m concurrent.futures.ProcessPoolExecutor() \u001b[38;5;28;01mas\u001b[39;00m pool:\n\u001b[32m---> \u001b[39m\u001b[32m17\u001b[39m     result = \u001b[38;5;28;01mawait\u001b[39;00m loop.run_in_executor(pool, cpu_bound_task)\n\u001b[32m     18\u001b[39m     \u001b[38;5;28mprint\u001b[39m(\u001b[33mf\u001b[39m\u001b[33m\"\u001b[39m\u001b[33mResult: \u001b[39m\u001b[38;5;132;01m{\u001b[39;00mresult\u001b[38;5;132;01m}\u001b[39;00m\u001b[33m\"\u001b[39m)\n",
      "\u001b[36mFile \u001b[39m\u001b[32m~/.pyenv/versions/3.13.0/lib/python3.13/asyncio/futures.py:288\u001b[39m, in \u001b[36mFuture.__await__\u001b[39m\u001b[34m(self)\u001b[39m\n\u001b[32m    286\u001b[39m \u001b[38;5;28;01mif\u001b[39;00m \u001b[38;5;129;01mnot\u001b[39;00m \u001b[38;5;28mself\u001b[39m.done():\n\u001b[32m    287\u001b[39m     \u001b[38;5;28mself\u001b[39m._asyncio_future_blocking = \u001b[38;5;28;01mTrue\u001b[39;00m\n\u001b[32m--> \u001b[39m\u001b[32m288\u001b[39m     \u001b[38;5;28;01myield\u001b[39;00m \u001b[38;5;28mself\u001b[39m  \u001b[38;5;66;03m# This tells Task to wait for completion.\u001b[39;00m\n\u001b[32m    289\u001b[39m \u001b[38;5;28;01mif\u001b[39;00m \u001b[38;5;129;01mnot\u001b[39;00m \u001b[38;5;28mself\u001b[39m.done():\n\u001b[32m    290\u001b[39m     \u001b[38;5;28;01mraise\u001b[39;00m \u001b[38;5;167;01mRuntimeError\u001b[39;00m(\u001b[33m\"\u001b[39m\u001b[33mawait wasn\u001b[39m\u001b[33m'\u001b[39m\u001b[33mt used with future\u001b[39m\u001b[33m\"\u001b[39m)\n",
      "\u001b[36mFile \u001b[39m\u001b[32m~/.pyenv/versions/3.13.0/lib/python3.13/asyncio/tasks.py:375\u001b[39m, in \u001b[36mTask.__wakeup\u001b[39m\u001b[34m(self, future)\u001b[39m\n\u001b[32m    373\u001b[39m \u001b[38;5;28;01mdef\u001b[39;00m\u001b[38;5;250m \u001b[39m\u001b[34m__wakeup\u001b[39m(\u001b[38;5;28mself\u001b[39m, future):\n\u001b[32m    374\u001b[39m     \u001b[38;5;28;01mtry\u001b[39;00m:\n\u001b[32m--> \u001b[39m\u001b[32m375\u001b[39m         \u001b[43mfuture\u001b[49m\u001b[43m.\u001b[49m\u001b[43mresult\u001b[49m\u001b[43m(\u001b[49m\u001b[43m)\u001b[49m\n\u001b[32m    376\u001b[39m     \u001b[38;5;28;01mexcept\u001b[39;00m \u001b[38;5;167;01mBaseException\u001b[39;00m \u001b[38;5;28;01mas\u001b[39;00m exc:\n\u001b[32m    377\u001b[39m         \u001b[38;5;66;03m# This may also be a cancellation.\u001b[39;00m\n\u001b[32m    378\u001b[39m         \u001b[38;5;28mself\u001b[39m.__step(exc)\n",
      "\u001b[36mFile \u001b[39m\u001b[32m~/.pyenv/versions/3.13.0/lib/python3.13/asyncio/futures.py:200\u001b[39m, in \u001b[36mFuture.result\u001b[39m\u001b[34m(self)\u001b[39m\n\u001b[32m    198\u001b[39m \u001b[38;5;28mself\u001b[39m.__log_traceback = \u001b[38;5;28;01mFalse\u001b[39;00m\n\u001b[32m    199\u001b[39m \u001b[38;5;28;01mif\u001b[39;00m \u001b[38;5;28mself\u001b[39m._exception \u001b[38;5;129;01mis\u001b[39;00m \u001b[38;5;129;01mnot\u001b[39;00m \u001b[38;5;28;01mNone\u001b[39;00m:\n\u001b[32m--> \u001b[39m\u001b[32m200\u001b[39m     \u001b[38;5;28;01mraise\u001b[39;00m \u001b[38;5;28mself\u001b[39m._exception.with_traceback(\u001b[38;5;28mself\u001b[39m._exception_tb)\n\u001b[32m    201\u001b[39m \u001b[38;5;28;01mreturn\u001b[39;00m \u001b[38;5;28mself\u001b[39m._result\n",
      "\u001b[31mBrokenProcessPool\u001b[39m: A process in the process pool was terminated abruptly while the future was running or pending."
     ]
    }
   ],
   "source": [
    "import asyncio\n",
    "import concurrent.futures\n",
    "\n",
    "def cpu_bound_task():\n",
    "    print(\"Start heavy CPU work\")\n",
    "    count = 0\n",
    "    for _ in range(10 ** 7):\n",
    "        count += 1\n",
    "    print(\"End heavy CPU work\")\n",
    "    return count\n",
    "\n",
    "async def main():\n",
    "    loop = asyncio.get_running_loop()\n",
    "\n",
    "    # CPU 바운드 작업을 ProcessPoolExecutor 로 분리\n",
    "    with concurrent.futures.ProcessPoolExecutor() as pool:\n",
    "        result = await loop.run_in_executor(pool, cpu_bound_task)\n",
    "        print(f\"Result: {result}\")\n",
    "\n",
    "if __name__ == '__main__':\n",
    "    asyncio.run(main())"
   ]
  }
 ],
 "metadata": {
  "kernelspec": {
   "display_name": "Python 3",
   "language": "python",
   "name": "python3"
  },
  "language_info": {
   "codemirror_mode": {
    "name": "ipython",
    "version": 3
   },
   "file_extension": ".py",
   "mimetype": "text/x-python",
   "name": "python",
   "nbconvert_exporter": "python",
   "pygments_lexer": "ipython3",
   "version": "3.13.0"
  }
 },
 "nbformat": 4,
 "nbformat_minor": 2
}
